Workbook

Sheet FF完整清单
A1: FF｜2026年9月维修配件成本
A2: 已保留 FF 手填成本；仅对同机型、同维修项目的 5 条空白记录套用 TW 成本。待补成本请到第二个工作表填写。
A4: 维修销售条目数 | B4: 43 | D4: 仍待补成本 | E4: =COUNTBLANK(F7:F49) -> 0 | G4: 1 AUD = CNY | H4: 4.7
A6: 日期 | B6: 工单号 | C6: 设备/机型 | D6: 维修项目 | E6: 销售额含 GST | F6: 单次配件成本 | G6: 货币 | H6: 成本 GST 口径 | I6: 成本 AUD 不含 GST | J6: 成本来源/备注
A7: 2026-09-03 | B7: RPR-1788395541264 | D7: Onsite/Remote Assistance - Insurance Report - Insurance Report | E7: 79 | F7: 0 | G7: AUD | I7: =IF(OR(F7="",NOT(ISNUMBER(F7))),"",IF(G7="CNY",F7/$H$4,IF(H7="含 GST",F7/1.1,IF(H7="不含 GST",F7,"")))) | J7: FF 已填
A8: 2026-09-03 | B8: RPR-1788397157905 | C8: Apple iPhone iPhone 14 Plus | D8: Apple iPhone - iPhone 14 Plus - Battery | E8: 159 | F8: 16 | G8: AUD | H8: 不含 GST | I8: =IF(OR(F8="",NOT(ISNUMBER(F8))),"",IF(G8="CNY",F8/$H$4,IF(H8="含 GST",F8/1.1,IF(H8="不含 GST",F8,"")))) -> 16 | J8: 参考 TW：Apple iPhone iPhone 14 Plus／Apple iPhone - iPhone 14 Plus - Battery
A9: 2026-09-03 | B9: RPR-1788397231929 | C9: Apple iPhone iPhone 14 Plus | D9: Apple iPhone - iPhone 14 Plus - Back Glass Replacement | E9: 179 | F9: =IF(待补成本!F5="","",待补成本!F5) -> 12 | G9: =IF(待补成本!G5="","",待补成本!G5) | H9: =IF(待补成本!H5="","",待补成本!H5) | I9: =IF(OR(F9="",NOT(ISNUMBER(F9))),"",IF(G9="CNY",F9/$H$4,IF(H9="含 GST",F9/1.1,IF(H9="不含 GST",F9,"")))) | J9: 待补成本
A10: 2026-09-03 | B10: RPR-1788399224416 | C10: Google Google Pixel 6A | D10: Google - Google Pixel 6A - Battery Replacement | E10: 100 | F10: =IF(待补成本!F6="","",待补成本!F6) -> 31 | G10: =IF(待补成本!G6="","",待补成本!G6) | H10: =IF(待补成本!H6="","",待补成本!H6) | I10: =IF(OR(F10="",NOT(ISNUMBER(F10))),"",IF(G10="CNY",F10/$H$4,IF(H10="含 GST",F10/1.1,IF(H10="不含 GST",F10,"")))) | J10: 待补成本
A11: 2026-09-03 | B11: RPR-1788413825545 | D11: Onsite/Remote Assistance - (Hardware) Phone/Tablet Inspection - (Hardware) Phone/Tablet Inspection | E11: 100 | F11: 0 | G11: AUD | I11: =IF(OR(F11="",NOT(ISNUMBER(F11))),"",IF(G11="CNY",F11/$H$4,IF(H11="含 GST",F11/1.1,IF(H11="不含 GST",F11,"")))) | J11: FF 已填
A12: 2026-09-03 | B12: RPR-1788417663663 | D12: Onsite/Remote Assistance - (Hardware) Phone/Tablet Inspection - (Hardware) Phone/Tablet Inspection | E12: 130 | F12: 0 | G12: AUD | I12: =IF(OR(F12="",NOT(ISNUMBER(F12))),"",IF(G12="CNY",F12/$H$4,IF(H12="含 GST",F12/1.1,IF(H12="不含 GST",F12,"")))) | J12: FF 已填
A13: 2026-09-05 | B13: RPR-1788571151451 | D13: (Hardware) Laptop/PC Inspection | E13: 99 | F13: 0 | G13: AUD | I13: =IF(OR(F13="",NOT(ISNUMBER(F13))),"",IF(G13="CNY",F13/$H$4,IF(H13="含 GST",F13/1.1,IF(H13="不含 GST",F13,"")))) | J13: FF 已填
A14: 2026-09-05 | B14: RPR-1788573730239 | D14: (Hardware) Phone/Tablet Inspection | E14: 59 | F14: 0 | G14: AUD | I14: =IF(OR(F14="",NOT(ISNUMBER(F14))),"",IF(G14="CNY",F14/$H$4,IF(H14="含 GST",F14/1.1,IF(H14="不含 GST",F14,"")))) | J14: FF 已填
A15: 2026-09-05 | B15: RPR-1788585154533 | C15: 17 pm lens | D15: 17 pm lens | E15: 159 | F15: =IF(待补成本!F7="","",待补成本!F7) -> 8 | G15: =IF(待补成本!G7="","",待补成本!G7) | H15: =IF(待补成本!H7="","",待补成本!H7) | I15: =IF(OR(F15="",NOT(ISNUMBER(F15))),"",IF(G15="CNY",F15/$H$4,IF(H15="含 GST",F15/1.1,IF(H15="不含 GST",F15,"")))) | J15: 待补成本
A16: 2026-09-05 | B16: RPR-1788573730239 | D16: 14 pro max back glass and charging port and battery | E16: 410 | F16: =IF(待补成本!F8="","",待补成本!F8) -> 50 | G16: =IF(待补成本!G8="","",待补成本!G8) | H16: =IF(待补成本!H8="","",待补成本!H8) | I16: =IF(OR(F16="",NOT(ISNUMBER(F16))),"",IF(G16="CNY",F16/$H$4,IF(H16="含 GST",F16/1.1,IF(H16="不含 GST",F16,"")))) | J16: 待补成本
A17: 2026-09-06 | B17: RPR-1788656888464 | C17: Samsung S Series Samsung S23 Ultra | D17: Samsung S Series - Samsung S23 Ultra - Screen Replacement | E17: 410 | F17: 156 | G17: AUD | H17: 不含 GST | I17: =IF(OR(F17="",NOT(ISNUMBER(F17))),"",IF(G17="CNY",F17/$H$4,IF(H17="含 GST",F17/1.1,IF(H17="不含 GST",F17,"")))) -> 156 | J17: 参考 TW：Samsung S Series Samsung S23 Ultra／Screen Replacement
A18: 2026-09-06 | B18: RPR-1788571151451 | D18: data back up | E18: 60 | F18: =IF(待补成本!F9="","",待补成本!F9) -> 0 | G18: =IF(待补成本!G9="","",待补成本!G9) | H18: =IF(待补成本!H9="","",待补成本!H9) | I18: =IF(OR(F18="",NOT(ISNUMBER(F18))),"",IF(G18="CNY",F18/$H$4,IF(H18="含 GST",F18/1.1,IF(H18="不含 GST",F18,"")))) | J18: 待补成本
A19: 2026-09-06 | B19: RPR-1788665113906 | C19: Apple iPhone iPhone 17 Pro Max | D19: Apple iPhone - iPhone 17 Pro Max - Screen Replacement (OLED) | E19: 289 | F19: =IF(待补成本!F10="","",待补成本!F10) -> 430 CNY | G19: =IF(待补成本!G10="","",待补成本!G10) | H19: =IF(待补成本!H10="","",待补成本!H10) | I19: =IF(OR(F19="",NOT(ISNUMBER(F19))),"",IF(G19="CNY",F19/$H$4,IF(H19="含 GST",F19/1.1,IF(H19="不含 GST",F19,"")))) | J19: 待补成本
A20: 2026-09-06 | B20: RPR-1788671603926 | C20: Apple iPhone iPhone 12 Pro Max | D20: Apple iPhone - iPhone 12 Pro Max - Screen Replacement (LCD) | E20: 149 | F20: =IF(待补成本!F11="","",待补成本!F11) -> 119 CNY | G20: =IF(待补成本!G11="","",待补成本!G11) | H20: =IF(待补成本!H11="","",待补成本!H11) | I20: =IF(OR(F20="",NOT(ISNUMBER(F20))),"",IF(G20="CNY",F20/$H$4,IF(H20="含 GST",F20/1.1,IF(H20="不含 GST",F20,"")))) | J20: 待补成本
A21: 2026-09-06 | B21: RPR-1788671663654 | C21: Apple iPhone iPhone 12 Pro Max | D21: Apple iPhone - iPhone 12 Pro Max - Charging Socket | E21: 149 | F21: =IF(待补成本!F12="","",待补成本!F12) -> 20 | G21: =IF(待补成本!G12="","",待补成本!G12) | H21: =IF(待补成本!H12="","",待补成本!H12) | I21: =IF(OR(F21="",NOT(ISNUMBER(F21))),"",IF(G21="CNY",F21/$H$4,IF(H21="含 GST",F21/1.1,IF(H21="不含 GST",F21,"")))) | J21: 待补成本
A22: 2026-09-07 | B22: RPR-1788764897931 | D22: Onsite/Remote Assistance - (Hardware) Phone/Tablet Inspection - (Hardware) Phone/Tablet Inspection | E22: 69 | F22: 0 | G22: AUD | I22: =IF(OR(F22="",NOT(ISNUMBER(F22))),"",IF(G22="CNY",F22/$H$4,IF(H22="含 GST",F22/1.1,IF(H22="不含 GST",F22,"")))) | J22: FF 已填
A23: 2026-09-08 | B23: RPR-1788845064758 | D23: Onsite/Remote Assistance - (Hardware) Laptop/PC Inspection - (Hardware) Laptop/PC Inspection | E23: 99 | F23: 0 | G23: AUD | I23: =IF(OR(F23="",NOT(ISNUMBER(F23))),"",IF(G23="CNY",F23/$H$4,IF(H23="含 GST",F23/1.1,IF(H23="不含 GST",F23,"")))) | J23: FF 已填
A24: 2026-09-09 | B24: RPR-1788910423514 | D24: Onsite/Remote Assistance - (Hardware) Phone/Tablet Inspection - (Hardware) Phone/Tablet Inspection | E24: 59 | F24: 0 | G24: AUD | I24: =IF(OR(F24="",NOT(ISNUMBER(F24))),"",IF(G24="CNY",F24/$H$4,IF(H24="含 GST",F24/1.1,IF(H24="不含 GST",F24,"")))) | J24: FF 已填
A25: 2026-09-09 | B25: RPR-1788910423514 | D25: (Hardware) Phone/Tablet Inspection | E25: 60 | F25: 0 | G25: AUD | I25: =IF(OR(F25="",NOT(ISNUMBER(F25))),"",IF(G25="CNY",F25/$H$4,IF(H25="含 GST",F25/1.1,IF(H25="不含 GST",F25,"")))) | J25: FF 已填
A26: 2026-09-09 | B26: RPR-1788913221783 | C26: Apple iPhone iPhone 13 | D26: Charging Socket | E26: 129 | F26: =IF(待补成本!F13="","",待补成本!F13) -> 20 | G26: =IF(待补成本!G13="","",待补成本!G13) | H26: =IF(待补成本!H13="","",待补成本!H13) | I26: =IF(OR(F26="",NOT(ISNUMBER(F26))),"",IF(G26="CNY",F26/$H$4,IF(H26="含 GST",F26/1.1,IF(H26="不含 GST",F26,"")))) | J26: 待补成本
A27: 2026-09-09 | B27: RPR-1788916220145 | C27: Apple iPhone iPhone 13 | D27: Battery | E27: 149 | F27: 45 | G27: CNY | H27: 不含 GST | I27: =IF(OR(F27="",NOT(ISNUMBER(F27))),"",IF(G27="CNY",F27/$H$4,IF(H27="含 GST",F27/1.1,IF(H27="不含 GST",F27,"")))) -> 9.5744681 | J27: 参考 TW：Apple iPhone iPhone 13／Battery
A28: 2026-09-10 | B28: RPR-1789023748341 | C28: Apple iPhone iPhone 11 | D28: Apple iPhone - iPhone 11 - Screen Replacement | E28: 129 | F28: 18 | G28: AUD | H28: 不含 GST | I28: =IF(OR(F28="",NOT(ISNUMBER(F28))),"",IF(G28="CNY",F28/$H$4,IF(H28="含 GST",F28/1.1,IF(H28="不含 GST",F28,"")))) -> 18 | J28: 参考 TW：Apple iPhone iPhone 11／Apple iPhone - iPhone 11 - Screen Replacement
A29: 2026-09-11 | B29: RPR-1789096276805 | D29: Onsite/Remote Assistance - (Hardware) Phone/Tablet Inspection - (Hardware) Phone/Tablet Inspection | E29: 59 | F29: 0 | G29: AUD | I29: =IF(OR(F29="",NOT(ISNUMBER(F29))),"",IF(G29="CNY",F29/$H$4,IF(H29="含 GST",F29/1.1,IF(H29="不含 GST",F29,"")))) | J29: FF 已填
A30: 2026-09-11 | B30: RPR-1789096276805 | D30: iphone se 3 battery replacement | E30: 30 | F30: 35 | G30: CNY | H30: 不含 GST | I30: =IF(OR(F30="",NOT(ISNUMBER(F30))),"",IF(G30="CNY",F30/$H$4,IF(H30="含 GST",F30/1.1,IF(H30="不含 GST",F30,"")))) -> 7.4468085 | J30: 参考 TW：Apple iPhone iPhone SE 3／Apple iPhone - iPhone SE 3 - Battery
A31: 2026-09-12 | B31: RPR-1789172281063 | D31: Onsite/Remote Assistance - (Hardware) Phone/Tablet Inspection - (Hardware) Phone/Tablet Inspection | E31: 59 | F31: 0 | G31: AUD | I31: =IF(OR(F31="",NOT(ISNUMBER(F31))),"",IF(G31="CNY",F31/$H$4,IF(H31="含 GST",F31/1.1,IF(H31="不含 GST",F31,"")))) | J31: FF 已填
A32: 2026-09-12 | B32: RPR-1789172281063 | D32: iphone 13 screen oled replacement | E32: 120.14 | F32: =IF(待补成本!F14="","",待补成本!F14) -> 217 CNY | G32: =IF(待补成本!G14="","",待补成本!G14) | H32: =IF(待补成本!H14="","",待补成本!H14) | I32: =IF(OR(F32="",NOT(ISNUMBER(F32))),"",IF(G32="CNY",F32/$H$4,IF(H32="含 GST",F32/1.1,IF(H32="不含 GST",F32,"")))) | J32: 待补成本
A33: 2026-09-12 | B33: RPR-1789172281063 | D33: iphone 13 battery replacement | E33: 136.74 | F33: =IF(待补成本!F15="","",待补成本!F15) -> 20 | G33: =IF(待补成本!G15="","",待补成本!G15) | H33: =IF(待补成本!H15="","",待补成本!H15) | I33: =IF(OR(F33="",NOT(ISNUMBER(F33))),"",IF(G33="CNY",F33/$H$4,IF(H33="含 GST",F33/1.1,IF(H33="不含 GST",F33,"")))) | J33: 待补成本
A34: 2026-09-14 | B34: RPR-1788764897931 | D34: dell p137G battery | E34: 130 | F34: 60 | G34: AUD | I34: =IF(OR(F34="",NOT(ISNUMBER(F34))),"",IF(G34="CNY",F34/$H$4,IF(H34="含 GST",F34/1.1,IF(H34="不含 GST",F34,"")))) | J34: FF 已填
A35: 2026-09-14 | B35: RPR-1789341518230 | D35: (Hardware) Phone/Tablet Inspection | E35: 59 | F35: 0 | G35: AUD | I35: =IF(OR(F35="",NOT(ISNUMBER(F35))),"",IF(G35="CNY",F35/$H$4,IF(H35="含 GST",F35/1.1,IF(H35="不含 GST",F35,"")))) | J35: FF 已填
A36: 2026-09-14 | B36: RPR-1789341518230 | D36: iphone se 2 battery replacement | E36: 12 | F36: 12 | G36: AUD | I36: =IF(OR(F36="",NOT(ISNUMBER(F36))),"",IF(G36="CNY",F36/$H$4,IF(H36="含 GST",F36/1.1,IF(H36="不含 GST",F36,"")))) | J36: FF 已填
A37: 2026-09-14 | B37: RPR-1789341518230 | D37: iphone se 2 charging socket | E37: 89 | F37: 12 | G37: AUD | I37: =IF(OR(F37="",NOT(ISNUMBER(F37))),"",IF(G37="CNY",F37/$H$4,IF(H37="含 GST",F37/1.1,IF(H37="不含 GST",F37,"")))) | J37: FF 已填
A38: 2026-09-16 | B38: RPR-1789526083105 | C38: Apple iPhone iPhone 12 Pro Max | D38: Apple iPhone - iPhone 12 Pro Max - Screen Replacement (LCD) | E38: 149 | F38: 20 | G38: AUD | I38: =IF(OR(F38="",NOT(ISNUMBER(F38))),"",IF(G38="CNY",F38/$H$4,IF(H38="含 GST",F38/1.1,IF(H38="不含 GST",F38,"")))) | J38: FF 已填
A39: 2026-09-19 | B39: RPR-1789785000572 | C39: Apple iPhone iPhone 16 Pro | D39: Apple iPhone - iPhone 16 Pro - Screen Replacement (OLED) | E39: 299 | F39: 290 | G39: CNY | I39: =IF(OR(F39="",NOT(ISNUMBER(F39))),"",IF(G39="CNY",F39/$H$4,IF(H39="含 GST",F39/1.1,IF(H39="不含 GST",F39,"")))) -> 61.702128 | J39: FF 已填
A40: 2026-09-19 | B40: RPR-1789798320779 | D40: Labor(Detail require) | E40: 30 | F40: 0 | G40: AUD | I40: =IF(OR(F40="",NOT(ISNUMBER(F40))),"",IF(G40="CNY",F40/$H$4,IF(H40="含 GST",F40/1.1,IF(H40="不含 GST",F40,"")))) | J40: FF 已填
A41: 2026-09-20 | B41: RPR-1789871157587 | D41: (Hardware) Laptop/PC Inspection | E41: 99 | F41: 0 | G41: AUD | I41: =IF(OR(F41="",NOT(ISNUMBER(F41))),"",IF(G41="CNY",F41/$H$4,IF(H41="含 GST",F41/1.1,IF(H41="不含 GST",F41,"")))) | J41: FF 已填
A42: 2026-09-21 | B42: RPR-1789957224109 | C42: Apple iPhone iPhone 13 | D42: Ear Speaker/Ear Speaker Flex | E42: 129 | F42: 10 | G42: AUD | I42: =IF(OR(F42="",NOT(ISNUMBER(F42))),"",IF(G42="CNY",F42/$H$4,IF(H42="含 GST",F42/1.1,IF(H42="不含 GST",F42,"")))) | J42: FF 已填
...

Sheet 待补成本
A1: FF｜TW 无同款维修的待补成本
A2: 只需填写黄色的单次配件成本、货币与 GST 口径；无用料填 0。1 AUD = 4.7 CNY。
A4: 日期 | B4: 工单号 | C4: 设备/机型 | D4: 维修项目 | E4: 销售额含 GST | F4: 单次配件成本 | G4: 货币 | H4: 成本 GST 口径
A5: 2026-09-03 | B5: RPR-1788397231929 | C5: Apple iPhone iPhone 14 Plus | D5: Apple iPhone - iPhone 14 Plus - Back Glass Replacement | E5: 179 | F5: 12
A6: 2026-09-03 | B6: RPR-1788399224416 | C6: Google Google Pixel 6A | D6: Google - Google Pixel 6A - Battery Replacement | E6: 100 | F6: 31
A7: 2026-09-05 | B7: RPR-1788585154533 | C7: 17 pm lens | D7: 17 pm lens | E7: 159 | F7: 8
A8: 2026-09-05 | B8: RPR-1788573730239 | D8: 14 pro max back glass and charging port and battery | E8: 410 | F8: 50
A9: 2026-09-06 | B9: RPR-1788571151451 | D9: data back up | E9: 60 | F9: 0
A10: 2026-09-06 | B10: RPR-1788665113906 | C10: Apple iPhone iPhone 17 Pro Max | D10: Apple iPhone - iPhone 17 Pro Max - Screen Replacement (OLED) | E10: 289 | F10: 430 CNY
A11: 2026-09-06 | B11: RPR-1788671603926 | C11: Apple iPhone iPhone 12 Pro Max | D11: Apple iPhone - iPhone 12 Pro Max - Screen Replacement (LCD) | E11: 149 | F11: 119 CNY
A12: 2026-09-06 | B12: RPR-1788671663654 | C12: Apple iPhone iPhone 12 Pro Max | D12: Apple iPhone - iPhone 12 Pro Max - Charging Socket | E12: 149 | F12: 20
A13: 2026-09-09 | B13: RPR-1788913221783 | C13: Apple iPhone iPhone 13 | D13: Charging Socket | E13: 129 | F13: 20
A14: 2026-09-12 | B14: RPR-1789172281063 | D14: iphone 13 screen oled replacement | E14: 120.14 | F14: 217 CNY
A15: 2026-09-12 | B15: RPR-1789172281063 | D15: iphone 13 battery replacement | E15: 136.74 | F15: 20
